Workbook
Name 名稱1: '[1]01參數設定'!#REF!
Name 名稱1: '[2]01參數設定'!#REF!
Name 名稱1: '01參數設定'!#REF!
Name 標案分析表: '[1]01參數設定'!#REF!
Name 標籤_本案及追加分析: [1]!表格_本案及追加分析[分類]
Name 標籤_本案及追加分析: [1]!表格_本案及追加分析[分類]
Name 標籤_本案及追加分析: 表格_本案及追加分析[分類]
Name 標籤_直接成本項目: [1]!表格_科目分類價格[分類]
Name 標籤_直接成本項目: [2]!表格_科目分類價格[分類]
Name 標籤_直接成本項目: 表格_科目分類價格[分類]
Name 標籤_群組分類項目: [1]!表格_群組分類價格[群組]
Name 標籤_群組分類項目: [2]!表格_群組分類價格[群組]
Name 標籤_群組分類項目: 表格_群組分類價格[群組]
Name 標籤_廠商分類: [1]!表格_廠商分類[公司名]
Name 標籤_廠商分類: [2]!表格_廠商分類[公司名]
Name 標籤_廠商分類: 表格_廠商分類[公司名]

Sheet 01參數設定
A1: 基本資訊
A2: 項目 | B2: 數值
A3: 專案編號 | C3: 填寫
A4: 專案名稱 | C4: 填寫
A5: 專案預算 | B5: 1000000 | C5: 填寫
A6: 業務人員 | C6: 填寫
A7: 專案經理 | C7: 填寫
A8: 專案執行部門 | C8: 填寫
A9: 製表日期 | C9: 填寫
A10: 製表人 | C10: 填寫
A11: 文件版本 | B11: a
A16: 歷史紀錄
A17: 版本 | B17: 日期 | C17: 說明
A18: V0 | B18: 2020.01.01 | C18: 文件初始版本
A19: V1 | B19: 2021.10.01 | C19: 修正成本統計表+報價分析
A20: V2 | B20: 2022.01.27 | C20: 1. 報價分析的毛利欄位，必須加入其他（'03 成本統計表'!$F$11），校正管銷部分＋保固等 部分 2. 餐費相關的項目，都要調整成 差旅費，校正毛利的計算 3. 增加。本案及追加的分類統計
A21: V3 | B21: 2022.02.13 | C21: 1. 改用報價為基底，換算出標準利潤率 2. 報價分析，加入 重要參考指標（成本，外部成本，內部費用） 3. 成本統計表中，加入『內部費用』為BOM 設定時可進行挑選 4. 恢復標案分析分頁，調整部分參數 ＊保險相關，不可納入內部費用中。
A22: V4 | B22: 2022.07.08 | C22: 1. 修正報價分析分頁中的內部成本計算方式，原先缺漏人工的計算，本版本補上 ＊保險相關，不可納入內部費用中。
A23: V5 | B23: 2023.02.11 | C23: 1. 加入直接成本及間接成本。 2. 直接成本為專案執行可動用範圍，間接成本屬於公司營運費用。 3. 加入專案管理所需的模板。 4. 未知風險 （管理階層授權），不得加入BOM表中。 由管理層承擔決定 5. 已知風險，加入BOM表當中． 6. 新增保險費及保固費的直接成本分類，修正對應關聯欄位 7. 報價分析，新增手動輸入欄位
A24: V6 | B24: 2023.11.10 | C24: 1. 參數說明修正 2. 內部費用改成管銷費用(名詞改變) 3. 直接成本改成關聯本案，並非統計追加與追減 4. 施工費改成施工_外包費 5. 未知風險改成其他 6. 新增津貼與補助，屬於外部成本 7. 新增臨櫃採購，由採購部同仁填寫

Sheet 03 成本統計表
A1: 成本分類(本案)
A2: 項次 | B2: 分類 | C2: 數量 | D2: 單位 | E2: 單價 | F2: 專案成本 | G2: BOM 占比
A3: 1 | B3: 人工 | C3: 1 | D3: 式 | E3: {=SUMPRODUCT((表格_BOM[Classification]=表格_科目分類價格[[#This Row],[分類]])*表格_BOM[Total Cost]*(表格_BOM[本案_追加]="本案"))} -> 2000 | F3: =表格_科目分類價格[[#This Row],[數量]]*表格_科目分類價格[[#This Row],[單價]] -> 2000 | G3: =表格_科目分類價格[[#This Row],[專案成本]]/表格_科目分類價格[[#Totals],[專案成本]] -> 0.58934465
A4: 2 | B4: 工程材料（硬體） | C4: 1 | D4: 式 | E4: {=SUMPRODUCT((表格_BOM[Classification]=表格_科目分類價格[[#This Row],[分類]])*表格_BOM[Total Cost]*(表格_BOM[本案_追加]="本案"))} -> 0 | F4: =表格_科目分類價格[[#This Row],[數量]]*表格_科目分類價格[[#This Row],[單價]] -> 0 | G4: =表格_科目分類價格[[#This Row],[專案成本]]/表格_科目分類價格[[#Totals],[專案成本]] -> 0
A5: 3 | B5: 工程材料（軟體） | C5: 1 | D5: 式 | E5: {=SUMPRODUCT((表格_BOM[Classification]=表格_科目分類價格[[#This Row],[分類]])*表格_BOM[Total Cost]*(表格_BOM[本案_追加]="本案"))} -> 0 | F5: =表格_科目分類價格[[#This Row],[數量]]*表格_科目分類價格[[#This Row],[單價]] -> 0 | G5: =表格_科目分類價格[[#This Row],[專案成本]]/表格_科目分類價格[[#Totals],[專案成本]] -> 0
A6: 4 | B6: 開發用設備材料 | C6: 1 | D6: 式 | E6: {=SUMPRODUCT((表格_BOM[Classification]=表格_科目分類價格[[#This Row],[分類]])*表格_BOM[Total Cost]*(表格_BOM[本案_追加]="本案"))} -> 0 | F6: =表格_科目分類價格[[#This Row],[數量]]*表格_科目分類價格[[#This Row],[單價]] -> 0 | G6: =表格_科目分類價格[[#This Row],[專案成本]]/表格_科目分類價格[[#Totals],[專案成本]] -> 0
A7: 5 | B7: 差旅費 | C7: 1 | D7: 式 | E7: {=SUMPRODUCT((表格_BOM[Classification]=表格_科目分類價格[[#This Row],[分類]])*表格_BOM[Total Cost]*(表格_BOM[本案_追加]="本案"))} -> 0 | F7: =表格_科目分類價格[[#This Row],[數量]]*表格_科目分類價格[[#This Row],[單價]] -> 0 | G7: =表格_科目分類價格[[#This Row],[專案成本]]/表格_科目分類價格[[#Totals],[專案成本]] -> 0
A8: 6 | B8: 施工_外包費 | C8: 1 | D8: 式 | E8: {=SUMPRODUCT((表格_BOM[Classification]=表格_科目分類價格[[#This Row],[分類]])*表格_BOM[Total Cost]*(表格_BOM[本案_追加]="本案"))} -> 0 | F8: =表格_科目分類價格[[#This Row],[數量]]*表格_科目分類價格[[#This Row],[單價]] -> 0 | G8: =表格_科目分類價格[[#This Row],[專案成本]]/表格_科目分類價格[[#Totals],[專案成本]] -> 0
A9: 7 | B9: 運輸費 | C9: 1 | D9: 式 | E9: {=SUMPRODUCT((表格_BOM[Classification]=表格_科目分類價格[[#This Row],[分類]])*表格_BOM[Total Cost]*(表格_BOM[本案_追加]="本案"))} -> 1000 | F9: =表格_科目分類價格[[#This Row],[數量]]*表格_科目分類價格[[#This Row],[單價]] -> 1000 | G9: =表格_科目分類價格[[#This Row],[專案成本]]/表格_科目分類價格[[#Totals],[專案成本]] -> 0.29467232
A10: 8 | B10: 進出口 | C10: 1 | D10: 式 | E10: {=SUMPRODUCT((表格_BOM[Classification]=表格_科目分類價格[[#This Row],[分類]])*表格_BOM[Total Cost]*(表格_BOM[本案_追加]="本案"))} -> 0 | F10: =表格_科目分類價格[[#This Row],[數量]]*表格_科目分類價格[[#This Row],[單價]] -> 0 | G10: =表格_科目分類價格[[#This Row],[專案成本]]/表格_科目分類價格[[#Totals],[專案成本]] -> 0
A11: 9 | B11: 保險費 | C11: 1 | D11: 式 | E11: {=SUMPRODUCT((表格_BOM[Classification]=表格_科目分類價格[[#This Row],[分類]])*表格_BOM[Total Cost]*(表格_BOM[本案_追加]="本案"))} -> 0 | F11: =表格_科目分類價格[[#This Row],[數量]]*表格_科目分類價格[[#This Row],[單價]] -> 0 | G11: =表格_科目分類價格[[#This Row],[專案成本]]/表格_科目分類價格[[#Totals],[專案成本]] -> 0
A12: 10 | B12: 保固費 | C12: 1 | D12: 式 | E12: {=SUMPRODUCT((表格_BOM[Classification]=表格_科目分類價格[[#This Row],[分類]])*表格_BOM[Total Cost]*(表格_BOM[本案_追加]="本案"))} -> 30 | F12: =表格_科目分類價格[[#This Row],[數量]]*表格_科目分類價格[[#This Row],[單價]] -> 30 | G12: =表格_科目分類價格[[#This Row],[專案成本]]/表格_科目分類價格[[#Totals],[專案成本]] -> 0.0088401697
A13: 11 | B13: 津貼與補助 | C13: 1 | D13: 式 | E13: {=SUMPRODUCT((表格_BOM[Classification]=表格_科目分類價格[[#This Row],[分類]])*表格_BOM[Total Cost]*(表格_BOM[本案_追加]="本案"))} -> 0 | F13: =表格_科目分類價格[[#This Row],[數量]]*表格_科目分類價格[[#This Row],[單價]] -> 0 | G13: =表格_科目分類價格[[#This Row],[專案成本]]/表格_科目分類價格[[#Totals],[專案成本]] -> 0
A14: 12 | B14: 管銷費用 | C14: 1 | D14: 式 | E14: {=SUMPRODUCT((表格_BOM[Classification]=表格_科目分類價格[[#This Row],[分類]])*表格_BOM[Total Cost]*(表格_BOM[本案_追加]="本案"))} -> 363.6 | F14: =表格_科目分類價格[[#This Row],[數量]]*表格_科目分類價格[[#This Row],[單價]] -> 363.6 | G14: =表格_科目分類價格[[#This Row],[專案成本]]/表格_科目分類價格[[#Totals],[專案成本]] -> 0.10714286
A15: 13 | B15: 其他 | C15: 1 | D15: 式 | E15: {=SUMPRODUCT((表格_BOM[Classification]=表格_科目分類價格[[#This Row],[分類]])*表格_BOM[Total Cost]*(表格_BOM[本案_追加]="本案"))} -> 0 | F15: =表格_科目分類價格[[#This Row],[數量]]*表格_科目分類價格[[#This Row],[單價]] -> 0 | G15: =表格_科目分類價格[[#This Row],[專案成本]]/表格_科目分類價格[[#Totals],[專案成本]] -> 0
A16: 合計(未稅) | F16: =SUBTOTAL(109,表格_科目分類價格[專案成本]) -> 3393.6 | G16: =SUBTOTAL(109,表格_科目分類價格[BOM 占比]) -> 1
A18: 報價用分類
A19: 項次 | B19: 群組 | C19: 數量 | D19: 單位 | E19: 單價 | F19: 專案成本 | G19: BOM 占比
A20: 1 | B20: 項目 | C20: 1 | D20: 式 | E20: {=SUMPRODUCT((表格_BOM[Group]=表格_群組分類價格[[#This Row],[群組]])*表格_BOM[Total Cost])} -> 0 | F20: =表格_群組分類價格[[#This Row],[數量]]*表格_群組分類價格[[#This Row],[單價]] -> 0 | G20: =表格_群組分類價格[[#This Row],[專案成本]]/表格_群組分類價格[[#Totals],[專案成本]] -> 0
A21: 2 | B21: 工程安裝 | C21: 1 | D21: 式 | E21: {=SUMPRODUCT((表格_BOM[Group]=表格_群組分類價格[[#This Row],[群組]])*表格_BOM[Total Cost])} -> 0 | F21: =表格_群組分類價格[[#This Row],[數量]]*表格_群組分類價格[[#This Row],[單價]] -> 0 | G21: =表格_群組分類價格[[#This Row],[專案成本]]/表格_群組分類價格[[#Totals],[專案成本]] -> 0
A22: 3 | B22: 規劃設計 | C22: 1 | D22: 式 | E22: {=SUMPRODUCT((表格_BOM[Group]=表格_群組分類價格[[#This Row],[群組]])*表格_BOM[Total Cost])} -> 0 | F22: =表格_群組分類價格[[#This Row],[數量]]*表格_群組分類價格[[#This Row],[單價]] -> 0 | G22: =表格_群組分類價格[[#This Row],[專案成本]]/表格_群組分類價格[[#Totals],[專案成本]] -> 0
A23: 4 | B23: 現場任務 | C23: 1 | D23: 式 | E23: {=SUMPRODUCT((表格_BOM[Group]=表格_群組分類價格[[#This Row],[群組]])*表格_BOM[Total Cost])} -> 0 | F23: =表格_群組分類價格[[#This Row],[數量]]*表格_群組分類價格[[#This Row],[單價]] -> 0 | G23: =表格_群組分類價格[[#This Row],[專案成本]]/表格_群組分類價格[[#Totals],[專案成本]] -> 0
A24: 5 | B24: 專案管理 | C24: 1 | D24: 式 | E24: {=SUMPRODUCT((表格_BOM[Group]=表格_群組分類價格[[#This Row],[群組]])*表格_BOM[Total Cost])} -> 3393.6 | F24: =表格_群組分類價格[[#This Row],[數量]]*表格_群組分類價格[[#This Row],[單價]] -> 3393.6 | G24: =表格_群組分類價格[[#This Row],[專案成本]]/表格_群組分類價格[[#Totals],[專案成本]] -> 1
A25: 合計(未稅) | F25: =SUBTOTAL(109,表格_群組分類價格[專案成本]) -> 3393.6 | G25: =SUBTOTAL(109,表格_群組分類價格[BOM 占比]) -> 1
A27: 廠商分類
A28: 項次 | B28: 公司名 | C28: 數量 | D28: 單位 | E28: 單價 | F28: 專案成本 | G28: BOM 占比
A29: 1 | B29: ICPSI | C29: 1 | D29: 式 | E29: {=SUMPRODUCT((表格_BOM[Manufacture]=表格_廠商分類[[#This Row],[公司名]])*表格_BOM[Total Cost])} -> 3393.6 | F29: =表格_廠商分類[[#This Row],[數量]]*表格_廠商分類[[#This Row],[單價]] -> 3393.6 | G29: =表格_廠商分類[[#This Row],[專案成本]]/表格_廠商分類[[#Totals],[專案成本]] -> 1
A30: 2 | B30: SIEMENS-SI | C30: 1 | D30: 式 | E30: {=SUMPRODUCT((表格_BOM[Manufacture]=表格_廠商分類[[#This Row],[公司名]])*表格_BOM[Total Cost])} -> 0 | F30: =表格_廠商分類[[#This Row],[數量]]*表格_廠商分類[[#This Row],[單價]] -> 0 | G30: =表格_廠商分類[[#This Row],[專案成本]]/表格_廠商分類[[#Totals],[專案成本]] -> 0
A31: 3 | B31: SIEMENS-DI | C31: 1 | D31: 式 | E31: {=SUMPRODUCT((表格_BOM[Manufacture]=表格_廠商分類[[#This Row],[公司名]])*表格_BOM[Total Cost])} -> 0 | F31: =表格_廠商分類[[#This Row],[數量]]*表格_廠商分類[[#This Row],[單價]] -> 0 | G31: =表格_廠商分類[[#This Row],[專案成本]]/表格_廠商分類[[#Totals],[專案成本]] -> 0
A32: 4 | B32: SATEC | C32: 1 | D32: 式 | E32: {=SUMPRODUCT((表格_BOM[Manufacture]=表格_廠商分類[[#This Row],[公司名]])*表格_BOM[Total Cost])} -> 0 | F32: =表格_廠商分類[[#This Row],[數量]]*表格_廠商分類[[#This Row],[單價]] -> 0 | G32: =表格_廠商分類[[#This Row],[專案成本]]/表格_廠商分類[[#Totals],[專案成本]] -> 0
A33: 5 | B33: Ficer | C33: 1 | D33: 式 | E33: {=SUMPRODUCT((表格_BOM[Manufacture]=表格_廠商分類[[#This Row],[公司名]])*表格_BOM[Total Cost])} -> 0 | F33: =表格_廠商分類[[#This Row],[數量]]*表格_廠商分類[[#This Row],[單價]] -> 0 | G33: =表格_廠商分類[[#This Row],[專案成本]]/表格_廠商分類[[#Totals],[專案成本]] -> 0
A34: 6 | B34: Heidi | C34: 1 | D34: 式 | E34: {=SUMPRODUCT((表格_BOM[Manufacture]=表格_廠商分類[[#This Row],[公司名]])*表格_BOM[Total Cost])} -> 0 | F34: =表格_廠商分類[[#This Row],[數量]]*表格_廠商分類[[#This Row],[單價]] -> 0 | G34: =表格_廠商分類[[#This Row],[專案成本]]/表格_廠商分類[[#Totals],[專案成本]] -> 0
A35: 7 | B35: 帆軟 | C35: 1 | D35: 式 | E35: {=SUMPRODUCT((表格_BOM[Manufacture]=表格_廠商分類[[#This Row],[公司名]])*表格_BOM[Total Cost])} -> 0 | F35: =表格_廠商分類[[#This Row],[數量]]*表格_廠商分類[[#This Row],[單價]] -> 0 | G35: =表格_廠商分類[[#This Row],[專案成本]]/表格_廠商分類[[#Totals],[專案成本]] -> 0
A36: 8 | B36: 宏傑 | C36: 1 | D36: 式 | E36: {=SUMPRODUCT((表格_BOM[Manufacture]=表格_廠商分類[[#This Row],[公司名]])*表格_BOM[Total Cost])} -> 0 | F36: =表格_廠商分類[[#This Row],[數量]]*表格_廠商分類[[#This Row],[單價]] -> 0 | G36: =表格_廠商分類[[#This Row],[專案成本]]/表格_廠商分類[[#Totals],[專案成本]] -> 0
A37: 9 | B37: 微軟 | C37: 1 | D37: 式 | E37: {=SUMPRODUCT((表格_BOM[Manufacture]=表格_廠商分類[[#This Row],[公司名]])*表格_BOM[Total Cost])} -> 0 | F37: =表格_廠商分類[[#This Row],[數量]]*表格_廠商分類[[#This Row],[單價]] -> 0 | G37: =表格_廠商分類[[#This Row],[專案成本]]/表格_廠商分類[[#Totals],[專案成本]] -> 0
A38: 10 | B38: FORTI | C38: 1 | D38: 式 | E38: {=SUMPRODUCT((表格_BOM[Manufacture]=表格_廠商分類[[#This Row],[公司名]])*表格_BOM[Total Cost])} -> 0 | F38: =表格_廠商分類[[#This Row],[數量]]*表格_廠商分類[[#This Row],[單價]] -> 0 | G38: =表格_廠商分類[[#This Row],[專案成本]]/表格_廠商分類[[#Totals],[專案成本]] -> 0
A39: 11 | B39: PCT | C39: 1 | D39: 式 | E39: {=SUMPRODUCT((表格_BOM[Manufacture]=表格_廠商分類[[#This Row],[公司名]])*表格_BOM[Total Cost])} -> 0 | F39: =表格_廠商分類[[#This Row],[數量]]*表格_廠商分類[[#This Row],[單價]] -> 0 | G39: =表格_廠商分類[[#This Row],[專案成本]]/表格_廠商分類[[#Totals],[專案成本]] -> 0
A40: 12 | B40: ViewSonic | C40: 1 | D40: 式 | E40: {=SUMPRODUCT((表格_BOM[Manufacture]=表格_廠商分類[[#This Row],[公司名]])*表格_BOM[Total Cost])} -> 0 | F40: =表格_廠商分類[[#This Row],[數量]]*表格_廠商分類[[#This Row],[單價]] -> 0 | G40: =表格_廠商分類[[#This Row],[專案成本]]/表格_廠商分類[[#Totals],[專案成本]] -> 0
... A54: 26 | B54: MIT | C54: 1 | D54: 式 | E54: {=SUMPRODUCT((表格_BOM[Manufacture]=表格_廠商分類[[#This Row],[公司名]])*表格_BOM[Total Cost])} -> 0 | F54: =表格_廠商分類[[#This Row],[數量]]*表格_廠商分類[[#This Row],[單價]] -> 0 | G54: =表格_廠商分類[[#This Row],[專案成本]]/表格_廠商分類[[#Totals],[專案成本]] -> 0
A55: 合計(未稅) | F55: =SUBTOTAL(109,表格_廠商分類[專案成本]) -> 3393.6 | G55: =SUBTOTAL(109,表格_廠商分類[BOM 占比]) -> 1
...

Sheet BOM
B2: ='01參數設定'!B3&"-"&'01參數設定'!B4 -> -
C4: NO | D4: Classification | E4: Group | F4: 本案_追加 | G4: Type | H4: Functional Description | I4: Manufacture | J4: Qty | K4: Unit | L4: Cost(未稅) | M4: Total Cost | N4: 第一次詢價 數量 | O4: 第一次詢價 單價(未稅) | P4: 第一次詢價 總價(未稅) | Q4: 下單價 (未稅) | R4: 下單價 (含稅) | S4: 交期 | T4: 付款條件 | U4: 採購單編號 | V4: 請款單號 | W4: 匯款日期 | X4: Note
B5: ="c" -> c | G5: **** 項目 **** | Q5: =表格_BOM[[#This Row],[下單價 (含稅)]]/1.05 -> 0
B6: ="c" -> c | D6: 工程材料（軟體） | E6: 項目 | F6: 本案 | Q6: =表格_BOM[[#This Row],[下單價 (含稅)]]/1.05 -> 0
B7: ="c" -> c | D7: 人工 | E7: 項目 | F7: 本案 | M7: =表格_BOM[[#This Row],[Qty]]*表格_BOM[[#This Row],[Cost(未稅)]] -> 0 | Q7: =表格_BOM[[#This Row],[下單價 (含稅)]]/1.05 -> 0
B8: ="c" -> c | G8: **** 工程安裝 **** | Q8: =表格_BOM[[#This Row],[下單價 (含稅)]]/1.05 -> 0
B9: ="c" -> c | D9: 人工 | E9: 工程安裝 | F9: 本案 | M9: =表格_BOM[[#This Row],[Qty]]*表格_BOM[[#This Row],[Cost(未稅)]] -> 0 | Q9: =表格_BOM[[#This Row],[下單價 (含稅)]]/1.05 -> 0
B10: ="c" -> c | D10: 人工 | E10: 工程安裝 | F10: 本案 | M10: =表格_BOM[[#This Row],[Qty]]*表格_BOM[[#This Row],[Cost(未稅)]] -> 0 | Q10: =表格_BOM[[#This Row],[下單價 (含稅)]]/1.05 -> 0
B11: ="c" -> c | G11: **** 規劃設計 **** | Q11: =表格_BOM[[#This Row],[下單價 (含稅)]]/1.05 -> 0
B12: ="c" -> c | D12: 人工 | E12: 規劃設計 | F12: 本案 | M12: =表格_BOM[[#This Row],[Qty]]*表格_BOM[[#This Row],[Cost(未稅)]] -> 0 | Q12: =表格_BOM[[#This Row],[下單價 (含稅)]]/1.05 -> 0
B13: ="c" -> c | D13: 人工 | E13: 規劃設計 | F13: 本案 | M13: =表格_BOM[[#This Row],[Qty]]*表格_BOM[[#This Row],[Cost(未稅)]] -> 0 | Q13: =表格_BOM[[#This Row],[下單價 (含稅)]]/1.05 -> 0
B14: ="c" -> c | G14: **** 現場任務 **** | Q14: =表格_BOM[[#This Row],[下單價 (含稅)]]/1.05 -> 0
B15: ="c" -> c | D15: 人工 | E15: 現場任務 | F15: 本案 | M15: =表格_BOM[[#This Row],[Qty]]*表格_BOM[[#This Row],[Cost(未稅)]] -> 0 | Q15: =表格_BOM[[#This Row],[下單價 (含稅)]]/1.05 -> 0
B16: ="c" -> c | D16: 人工 | E16: 現場任務 | F16: 本案 | M16: =表格_BOM[[#This Row],[Qty]]*表格_BOM[[#This Row],[Cost(未稅)]] -> 0 | Q16: =表格_BOM[[#This Row],[下單價 (含稅)]]/1.05 -> 0
B17: ="c" -> c | G17: **** 專案管理 **** | Q17: =表格_BOM[[#This Row],[下單價 (含稅)]]/1.05 -> 0
B18: ="c" -> c | D18: 人工 | E18: 專案管理 | F18: 本案 | G18: 專案管理 | I18: ICPSI | J18: 0.5 | K18: 天 | L18: 4000 | M18: =表格_BOM[[#This Row],[Qty]]*表格_BOM[[#This Row],[Cost(未稅)]] -> 2000 | Q18: =表格_BOM[[#This Row],[下單價 (含稅)]]/1.05 -> 0
B19: ="c" -> c | D19: 運輸費 | E19: 專案管理 | F19: 本案 | G19: 公文來往寄信及包裹 | I19: ICPSI | J19: 0 | K19: 式 | L19: 5000 | M19: =表格_BOM[[#This Row],[Qty]]*表格_BOM[[#This Row],[Cost(未稅)]] -> 0 | Q19: =表格_BOM[[#This Row],[下單價 (含稅)]]/1.05 -> 0
B20: ="c" -> c | D20: 運輸費 | E20: 專案管理 | F20: 本案 | G20: 產品運輸費 | H20: 驗收物品 來回運送用 | I20: ICPSI | J20: 1 | K20: 式 | L20: 1000 | M20: =表格_BOM[[#This Row],[Qty]]*表格_BOM[[#This Row],[Cost(未稅)]] -> 1000 | Q20: =表格_BOM[[#This Row],[下單價 (含稅)]]/1.05 -> 0
B21: ="c" -> c | D21: 保險費 | E21: 專案管理 | F21: 本案 | G21: 工程保險 | I21: 富邦 | J21: 0 | K21: 式 | L21: 30000 | M21: =表格_BOM[[#This Row],[Qty]]*表格_BOM[[#This Row],[Cost(未稅)]] -> 0 | Q21: =表格_BOM[[#This Row],[下單價 (含稅)]]/1.05 -> 0
B22: ="c" -> c | D22: 差旅費 | E22: 專案管理 | F22: 本案 | G22: 餐費/業務 | H22: 現場業務費用 | I22: ICPSI | J22: 0 | K22: 式 | L22: 20000 | M22: =表格_BOM[[#This Row],[Qty]]*表格_BOM[[#This Row],[Cost(未稅)]] -> 0 | Q22: =表格_BOM[[#This Row],[下單價 (含稅)]]/1.05 -> 0
B23: ="c" -> c | D23: 工程材料（硬體） | E23: 專案管理 | F23: 本案 | G23: 已知風險 | H23: 應變準備金，總金額之3% | I23: ICPSI | J23: 0 | K23: 式 | L23: =SUM($M$5:M21)*3% -> 90 | M23: =表格_BOM[[#This Row],[Qty]]*表格_BOM[[#This Row],[Cost(未稅)]] -> 0 | Q23: =表格_BOM[[#This Row],[下單價 (含稅)]]/1.05 -> 0
B24: ="c" -> c | D24: 保固費 | E24: 專案管理 | F24: 本案 | G24: 專案保固 | H24: 總金額之1%/年 | I24: ICPSI | J24: 1 | K24: 年 | L24: =SUM($M$5:M23)*1% -> 30 | M24: =表格_BOM[[#This Row],[Qty]]*表格_BOM[[#This Row],[Cost(未稅)]] -> 30 | Q24: =表格_BOM[[#This Row],[下單價 (含稅)]]/1.05 -> 0
B25: ="c" -> c | D25: 其他 | E25: 專案管理 | F25: 本案 | G25: 未知風險 | H25: 管理階層決定，總金額0% | I25: ICPSI | J25: 1 | K25: 式 | L25: 0 | M25: =表格_BOM[[#This Row],[Qty]]*表格_BOM[[#This Row],[Cost(未稅)]] -> 0 | Q25: =表格_BOM[[#This Row],[下單價 (含稅)]]/1.05 -> 0
B26: ="c" -> c | D26: 管銷費用 | E26: 專案管理 | F26: 本案 | G26: 管銷費用 | H26: 12%，間接成本（不可使用費用） | I26: ICPSI | J26: 1 | K26: 式 | L26: =SUM($M$5:M24)*12% -> 363.6 | M26: =表格_BOM[[#This Row],[Qty]]*表格_BOM[[#This Row],[Cost(未稅)]] -> 363.6 | Q26: =表格_BOM[[#This Row],[下單價 (含稅)]]/1.05 -> 0
B27: ="c" -> c | G27: **** 追加 **** | Q27: =表格_BOM[[#This Row],[下單價 (含稅)]]/1.05 -> 0
B28: ="c" -> c | F28: 追加 | M28: =表格_BOM[[#This Row],[Qty]]*表格_BOM[[#This Row],[Cost(未稅)]] -> 0 | Q28: =表格_BOM[[#This Row],[下單價 (含稅)]]/1.05 -> 0
B29: ="c" -> c | F29: 追加 | M29: =表格_BOM[[#This Row],[Qty]]*表格_BOM[[#This Row],[Cost(未稅)]] -> 0 | Q29: =表格_BOM[[#This Row],[下單價 (含稅)]]/1.05 -> 0
B30: ="c" -> c | F30: 追加 | M30: =表格_BOM[[#This Row],[Qty]]*表格_BOM[[#This Row],[Cost(未稅)]] -> 0 | Q30: =表格_BOM[[#This Row],[下單價 (含稅)]]/1.05 -> 0
B31: ="c" -> c | F31: 追加 | M31: =表格_BOM[[#This Row],[Qty]]*表格_BOM[[#This Row],[Cost(未稅)]] -> 0 | Q31: =表格_BOM[[#This Row],[下單價 (含稅)]]/1.05 -> 0
B32: ="c" -> c | F32: 追加 | M32: =表格_BOM[[#This Row],[Qty]]*表格_BOM[[#This Row],[Cost(未稅)]] -> 0 | Q32: =表格_BOM[[#This Row],[下單價 (含稅)]]/1.05 -> 0
B33: ="c" -> c | F33: 追加 | M33: =表格_BOM[[#This Row],[Qty]]*表格_BOM[[#This Row],[Cost(未稅)]] -> 0 | Q33: =表格_BOM[[#This Row],[下單價 (含稅)]]/1.05 -> 0
B34: ="c" -> c | F34: 追加 | M34: =表格_BOM[[#This Row],[Qty]]*表格_BOM[[#This Row],[Cost(未稅)]] -> 0 | Q34: =表格_BOM[[#This Row],[下單價 (含稅)]]/1.05 -> 0
B35: ="c" -> c | G35: **** 追減 **** | Q35: =表格_BOM[[#This Row],[下單價 (含稅)]]/1.05 -> 0
B36: ="c" -> c | F36: 追減 | M36: =表格_BOM[[#This Row],[Qty]]*表格_BOM[[#This Row],[Cost(未稅)]] -> 0 | Q36: =表格_BOM[[#This Row],[下單價 (含稅)]]/1.05 -> 0
B37: ="c" -> c | F37: 追減 | M37: =表格_BOM[[#This Row],[Qty]]*表格_BOM[[#This Row],[Cost(未稅)]] -> 0 | Q37: =表格_BOM[[#This Row],[下單價 (含稅)]]/1.05 -> 0
B38: ="c" -> c | F38: 追減 | M38: =表格_BOM[[#This Row],[Qty]]*表格_BOM[[#This Row],[Cost(未稅)]] -> 0 | Q38: =表格_BOM[[#This Row],[下單價 (含稅)]]/1.05 -> 0
B39: ="c" -> c | F39: 追減 | Q39: =表格_BOM[[#This Row],[下單價 (含稅)]]/1.05 -> 0
B40: ="c" -> c | M40: =表格_BOM[[#This Row],[Qty]]*表格_BOM[[#This Row],[Cost(未稅)]] -> 0 | Q40: =表格_BOM[[#This Row],[下單價 (含稅)]]/1.05 -> 0
B41: ="c" -> c | G41: **** 臨櫃採購 **** | Q41: =表格_BOM[[#This Row],[下單價 (含稅)]]/1.05 -> 0
B42: ="c" -> c | D42: 其他 | F42: 追加 | M42: =表格_BOM[[#This Row],[Qty]]*表格_BOM[[#This Row],[Cost(未稅)]] -> 0 | Q42: =表格_BOM[[#This Row],[下單價 (含稅)]]/1.05 -> 0
...

Sheet 報價分析
A1: ='01參數設定'!$B$4&"報價分析表(預算"&'01參數設定'!$B$5&")" -> 報價分析表(預算1000000) | H1: 總成本 | I1: =表格_科目分類價格[[#Totals],[專案成本]] -> 3393.6 | K1: 內部費用 | L1: ='03 成本統計表'!F3+'03 成本統計表'!F14+'03 成本統計表'!F13 -> 2363.6
A2: 報價金額(未稅) | B2: 利潤 | C2: 利潤率 | D2: 毛利 | E2: 毛利率 | F2: 倍率(不參考) | H2: 外部成本 | I2: =SUM('03 成本統計表'!$F$4:$F$12)+'03 成本統計表'!$F$15 -> 1030
A3: =10000000 -> 10000000 | B3: =表格_報價分析表[[#This Row],[報價金額(未稅)]]-表格_BOM[[#Totals],[Total Cost]] -> 9996606.4 | C3: =表格_報價分析表[[#This Row],[利潤]]/表格_報價分析表[[#This Row],[報價金額(未稅)]] -> 0.99966064 | D3: =表格_報價分析表[[#This Row],[報價金額(未稅)]]-表格_BOM[[#Totals],[Total Cost]]+'03 成本統計表'!$F$3+'03 成本統計表'!$F$14 -> 9998970 | E3: =(D3)/表格_報價分析表[[#This Row],[報價金額(未稅)]] -> 0.999897 | F3: 手動填寫
A4: =表格_BOM[[#Totals],[Total Cost]]*(100%+表格_報價分析表[[#This Row],[倍率(不參考)]]) -> 3427.536 | B4: =表格_報價分析表[[#This Row],[報價金額(未稅)]]-表格_BOM[[#Totals],[Total Cost]] -> 33.936 | C4: =表格_報價分析表[[#This Row],[利潤]]/表格_報價分析表[[#This Row],[報價金額(未稅)]] -> 0.0099009901 | D4: =表格_報價分析表[[#This Row],[報價金額(未稅)]]-表格_BOM[[#Totals],[Total Cost]]+'03 成本統計表'!$F$3+'03 成本統計表'!$F$14 -> 2397.536 | E4: =(D4)/表格_報價分析表[[#This Row],[報價金額(未稅)]] -> 0.69949258 | F4: 0.01
A5: =表格_BOM[[#Totals],[Total Cost]]*(100%+表格_報價分析表[[#This Row],[倍率(不參考)]]) -> 3461.472 | B5: =表格_報價分析表[[#This Row],[報價金額(未稅)]]-表格_BOM[[#Totals],[Total Cost]] -> 67.872 | C5: =表格_報價分析表[[#This Row],[利潤]]/表格_報價分析表[[#This Row],[報價金額(未稅)]] -> 0.019607843 | D5: =表格_報價分析表[[#This Row],[報價金額(未稅)]]-表格_BOM[[#Totals],[Total Cost]]+'03 成本統計表'!$F$3+'03 成本統計表'!$F$14 -> 2431.472 | E5: =(D5)/表格_報價分析表[[#This Row],[報價金額(未稅)]] -> 0.70243873 | F5: 0.02 | H5: 專案報價及成本細節
A6: =表格_BOM[[#Totals],[Total Cost]]*(100%+表格_報價分析表[[#This Row],[倍率(不參考)]]) -> 3495.408 | B6: =表格_報價分析表[[#This Row],[報價金額(未稅)]]-表格_BOM[[#Totals],[Total Cost]] -> 101.808 | C6: =表格_報價分析表[[#This Row],[利潤]]/表格_報價分析表[[#This Row],[報價金額(未稅)]] -> 0.029126214 | D6: =表格_報價分析表[[#This Row],[報價金額(未稅)]]-表格_BOM[[#Totals],[Total Cost]]+'03 成本統計表'!$F$3+'03 成本統計表'!$F$14 -> 2465.408 | E6: =(D6)/表格_報價分析表[[#This Row],[報價金額(未稅)]] -> 0.70532768 | F6: 0.03 | H6: 報價金額(未稅) | I6: =A3 -> 10000000
A7: =表格_BOM[[#Totals],[Total Cost]]*(100%+表格_報價分析表[[#This Row],[倍率(不參考)]]) -> 3529.344 | B7: =表格_報價分析表[[#This Row],[報價金額(未稅)]]-表格_BOM[[#Totals],[Total Cost]] -> 135.744 | C7: =表格_報價分析表[[#This Row],[利潤]]/表格_報價分析表[[#This Row],[報價金額(未稅)]] -> 0.038461538 | D7: =表格_報價分析表[[#This Row],[報價金額(未稅)]]-表格_BOM[[#Totals],[Total Cost]]+'03 成本統計表'!$F$3+'03 成本統計表'!$F$14 -> 2499.344 | E7: =(D7)/表格_報價分析表[[#This Row],[報價金額(未稅)]] -> 0.70816106 | F7: 0.04 | H7: 外部成本 | I7: =I2 -> 1030
A8: =表格_BOM[[#Totals],[Total Cost]]*(100%+表格_報價分析表[[#This Row],[倍率(不參考)]]) -> 3563.28 | B8: =表格_報價分析表[[#This Row],[報價金額(未稅)]]-表格_BOM[[#Totals],[Total Cost]] -> 169.68 | C8: =表格_報價分析表[[#This Row],[利潤]]/表格_報價分析表[[#This Row],[報價金額(未稅)]] -> 0.047619048 | D8: =表格_報價分析表[[#This Row],[報價金額(未稅)]]-表格_BOM[[#Totals],[Total Cost]]+'03 成本統計表'!$F$3+'03 成本統計表'!$F$14 -> 2533.28 | E8: =(D8)/表格_報價分析表[[#This Row],[報價金額(未稅)]] -> 0.71094048 | F8: 0.05 | H8: 內部費用 | I8: =L1 -> 2363.6
A9: =表格_BOM[[#Totals],[Total Cost]]*(100%+表格_報價分析表[[#This Row],[倍率(不參考)]]) -> 3597.216 | B9: =表格_報價分析表[[#This Row],[報價金額(未稅)]]-表格_BOM[[#Totals],[Total Cost]] -> 203.616 | C9: =表格_報價分析表[[#This Row],[利潤]]/表格_報價分析表[[#This Row],[報價金額(未稅)]] -> 0.056603774 | D9: =表格_報價分析表[[#This Row],[報價金額(未稅)]]-表格_BOM[[#Totals],[Total Cost]]+'03 成本統計表'!$F$3+'03 成本統計表'!$F$14 -> 2567.216 | E9: =(D9)/表格_報價分析表[[#This Row],[報價金額(未稅)]] -> 0.71366746 | F9: 0.06 | H9: 總成本 | I9: =I1 -> 3393.6
A10: =表格_BOM[[#Totals],[Total Cost]]*(100%+表格_報價分析表[[#This Row],[倍率(不參考)]]) -> 3631.152 | B10: =表格_報價分析表[[#This Row],[報價金額(未稅)]]-表格_BOM[[#Totals],[Total Cost]] -> 237.552 | C10: =表格_報價分析表[[#This Row],[利潤]]/表格_報價分析表[[#This Row],[報價金額(未稅)]] -> 0.065420561 | D10: =表格_報價分析表[[#This Row],[報價金額(未稅)]]-表格_BOM[[#Totals],[Total Cost]]+'03 成本統計表'!$F$3+'03 成本統計表'!$F$14 -> 2601.152 | E10: =(D10)/表格_報價分析表[[#This Row],[報價金額(未稅)]] -> 0.71634346 | F10: 0.07 | H10: 利潤率 | I10: =C3 -> 0.99966064
A11: =表格_BOM[[#Totals],[Total Cost]]*(100%+表格_報價分析表[[#This Row],[倍率(不參考)]]) -> 3665.088 | B11: =表格_報價分析表[[#This Row],[報價金額(未稅)]]-表格_BOM[[#Totals],[Total Cost]] -> 271.488 | C11: =表格_報價分析表[[#This Row],[利潤]]/表格_報價分析表[[#This Row],[報價金額(未稅)]] -> 0.074074074 | D11: =表格_報價分析表[[#This Row],[報價金額(未稅)]]-表格_BOM[[#Totals],[Total Cost]]+'03 成本統計表'!$F$3+'03 成本統計表'!$F$14 -> 2635.088 | E11: =(D11)/表格_報價分析表[[#This Row],[報價金額(未稅)]] -> 0.71896991 | F11: 0.08 | H11: 利潤 | I11: =B3 -> 9996606.4
A12: =表格_BOM[[#Totals],[Total Cost]]*(100%+表格_報價分析表[[#This Row],[倍率(不參考)]]) -> 3699.024 | B12: =表格_報價分析表[[#This Row],[報價金額(未稅)]]-表格_BOM[[#Totals],[Total Cost]] -> 305.424 | C12: =表格_報價分析表[[#This Row],[利潤]]/表格_報價分析表[[#This Row],[報價金額(未稅)]] -> 0.082568807 | D12: =表格_報價分析表[[#This Row],[報價金額(未稅)]]-表格_BOM[[#Totals],[Total Cost]]+'03 成本統計表'!$F$3+'03 成本統計表'!$F$14 -> 2669.024 | E12: =(D12)/表格_報價分析表[[#This Row],[報價金額(未稅)]] -> 0.72154817 | F12: 0.09 | H12: 毛利率 | I12: =E3 -> 0.999897
A13: =表格_BOM[[#Totals],[Total Cost]]*(100%+表格_報價分析表[[#This Row],[倍率(不參考)]]) -> 3732.96 | B13: =表格_報價分析表[[#This Row],[報價金額(未稅)]]-表格_BOM[[#Totals],[Total Cost]] -> 339.36 | C13: =表格_報價分析表[[#This Row],[利潤]]/表格_報價分析表[[#This Row],[報價金額(未稅)]] -> 0.090909091 | D13: =表格_報價分析表[[#This Row],[報價金額(未稅)]]-表格_BOM[[#Totals],[Total Cost]]+'03 成本統計表'!$F$3+'03 成本統計表'!$F$14 -> 2702.96 | E13: =(D13)/表格_報價分析表[[#This Row],[報價金額(未稅)]] -> 0.72407955 | F13: 0.1 | H13: 毛利 | I13: =D3 -> 9998970
A14: =表格_BOM[[#Totals],[Total Cost]]*(100%+表格_報價分析表[[#This Row],[倍率(不參考)]]) -> 3766.896 | B14: =表格_報價分析表[[#This Row],[報價金額(未稅)]]-表格_BOM[[#Totals],[Total Cost]] -> 373.296 | C14: =表格_報價分析表[[#This Row],[利潤]]/表格_報價分析表[[#This Row],[報價金額(未稅)]] -> 0.099099099 | D14: =表格_報價分析表[[#This Row],[報價金額(未稅)]]-表格_BOM[[#Totals],[Total Cost]]+'03 成本統計表'!$F$3+'03 成本統計表'!$F$14 -> 2736.896 | E14: =(D14)/表格_報價分析表[[#This Row],[報價金額(未稅)]] -> 0.72656532 | F14: 0.11
A15: =表格_BOM[[#Totals],[Total Cost]]*(100%+表格_報價分析表[[#This Row],[倍率(不參考)]]) -> 3800.832 | B15: =表格_報價分析表[[#This Row],[報價金額(未稅)]]-表格_BOM[[#Totals],[Total Cost]] -> 407.232 | C15: =表格_報價分析表[[#This Row],[利潤]]/表格_報價分析表[[#This Row],[報價金額(未稅)]] -> 0.10714286 | D15: =表格_報價分析表[[#This Row],[報價金額(未稅)]]-表格_BOM[[#Totals],[Total Cost]]+'03 成本統計表'!$F$3+'03 成本統計表'!$F$14 -> 2770.832 | E15: =(D15)/表格_報價分析表[[#This Row],[報價金額(未稅)]] -> 0.7290067 | F15: 0.12
A16: =表格_BOM[[#Totals],[Total Cost]]*(100%+表格_報價分析表[[#This Row],[倍率(不參考)]]) -> 3834.768 | B16: =表格_報價分析表[[#This Row],[報價金額(未稅)]]-表格_BOM[[#Totals],[Total Cost]] -> 441.168 | C16: =表格_報價分析表[[#This Row],[利潤]]/表格_報價分析表[[#This Row],[報價金額(未稅)]] -> 0.11504425 | D16: =表格_報價分析表[[#This Row],[報價金額(未稅)]]-表格_BOM[[#Totals],[Total Cost]]+'03 成本統計表'!$F$3+'03 成本統計表'!$F$14 -> 2804.768 | E16: =(D16)/表格_報價分析表[[#This Row],[報價金額(未稅)]] -> 0.73140487 | F16: 0.13
A17: =表格_BOM[[#Totals],[Total Cost]]*(100%+表格_報價分析表[[#This Row],[倍率(不參考)]]) -> 3868.704 | B17: =表格_報價分析表[[#This Row],[報價金額(未稅)]]-表格_BOM[[#Totals],[Total Cost]] -> 475.104 | C17: =表格_報價分析表[[#This Row],[利潤]]/表格_報價分析表[[#This Row],[報價金額(未稅)]] -> 0.12280702 | D17: =表格_報價分析表[[#This Row],[報價金額(未稅)]]-表格_BOM[[#Totals],[Total Cost]]+'03 成本統計表'!$F$3+'03 成本統計表'!$F$14 -> 2838.704 | E17: =(D17)/表格_報價分析表[[#This Row],[報價金額(未稅)]] -> 0.73376097 | F17: 0.14
A18: =表格_BOM[[#Totals],[Total Cost]]*(100%+表格_報價分析表[[#This Row],[倍率(不參考)]]) -> 3902.64 | B18: =表格_報價分析表[[#This Row],[報價金額(未稅)]]-表格_BOM[[#Totals],[Total Cost]] -> 509.04 | C18: =表格_報價分析表[[#This Row],[利潤]]/表格_報價分析表[[#This Row],[報價金額(未稅)]] -> 0.13043478 | D18: =表格_報價分析表[[#This Row],[報價金額(未稅)]]-表格_BOM[[#Totals],[Total Cost]]+'03 成本統計表'!$F$3+'03 成本統計表'!$F$14 -> 2872.64 | E18: =(D18)/表格_報價分析表[[#This Row],[報價金額(未稅)]] -> 0.73607609 | F18: 0.15
A19: =表格_BOM[[#Totals],[Total Cost]]*(100%+表格_報價分析表[[#This Row],[倍率(不參考)]]) -> 3936.576 | B19: =表格_報價分析表[[#This Row],[報價金額(未稅)]]-表格_BOM[[#Totals],[Total Cost]] -> 542.976 | C19: =表格_報價分析表[[#This Row],[利潤]]/表格_報價分析表[[#This Row],[報價金額(未稅)]] -> 0.13793103 | D19: =表格_報價分析表[[#This Row],[報價金額(未稅)]]-表格_BOM[[#Totals],[Total Cost]]+'03 成本統計表'!$F$3+'03 成本統計表'!$F$14 -> 2906.576 | E19: =(D19)/表格_報價分析表[[#This Row],[報價金額(未稅)]] -> 0.7383513 | F19: 0.16
A20: =表格_BOM[[#Totals],[Total Cost]]*(100%+表格_報價分析表[[#This Row],[倍率(不參考)]]) -> 3970.512 | B20: =表格_報價分析表[[#This Row],[報價金額(未稅)]]-表格_BOM[[#Totals],[Total Cost]] -> 576.912 | C20: =表格_報價分析表[[#This Row],[利潤]]/表格_報價分析表[[#This Row],[報價金額(未稅)]] -> 0.14529915 | D20: =表格_報價分析表[[#This Row],[報價金額(未稅)]]-表格_BOM[[#Totals],[Total Cost]]+'03 成本統計表'!$F$3+'03 成本統計表'!$F$14 -> 2940.512 | E20: =(D20)/表格_報價分析表[[#This Row],[報價金額(未稅)]] -> 0.74058761 | F20: 0.17
A21: =表格_BOM[[#Totals],[Total Cost]]*(100%+表格_報價分析表[[#This Row],[倍率(不參考)]]) -> 4004.448 | B21: =表格_報價分析表[[#This Row],[報價金額(未稅)]]-表格_BOM[[#Totals],[Total Cost]] -> 610.848 | C21: =表格_報價分析表[[#This Row],[利潤]]/表格_報價分析表[[#This Row],[報價金額(未稅)]] -> 0.15254237 | D21: =表格_報價分析表[[#This Row],[報價金額(未稅)]]-表格_BOM[[#Totals],[Total Cost]]+'03 成本統計表'!$F$3+'03 成本統計表'!$F$14 -> 2974.448 | E21: =(D21)/表格_報價分析表[[#This Row],[報價金額(未稅)]] -> 0.74278602 | F21: 0.18
A22: =表格_BOM[[#Totals],[Total Cost]]*(100%+表格_報價分析表[[#This Row],[倍率(不參考)]]) -> 4038.384 | B22: =表格_報價分析表[[#This Row],[報價金額(未稅)]]-表格_BOM[[#Totals],[Total Cost]] -> 644.784 | C22: =表格_報價分析表[[#This Row],[利潤]]/表格_報價分析表[[#This Row],[報價金額(未稅)]] -> 0.15966387 | D22: =表格_報價分析表[[#This Row],[報價金額(未稅)]]-表格_BOM[[#Totals],[Total Cost]]+'03 成本統計表'!$F$3+'03 成本統計表'!$F$14 -> 3008.384 | E22: =(D22)/表格_報價分析表[[#This Row],[報價金額(未稅)]] -> 0.74494748 | F22: 0.19
A23: =表格_BOM[[#Totals],[Total Cost]]*(100%+表格_報價分析表[[#This Row],[倍率(不參考)]]) -> 4072.32 | B23: =表格_報價分析表[[#This Row],[報價金額(未稅)]]-表格_BOM[[#Totals],[Total Cost]] -> 678.72 | C23: =表格_報價分析表[[#This Row],[利潤]]/表格_報價分析表[[#This Row],[報價金額(未稅)]] -> 0.16666667 | D23: =表格_報價分析表[[#This Row],[報價金額(未稅)]]-表格_BOM[[#Totals],[Total Cost]]+'03 成本統計表'!$F$3+'03 成本統計表'!$F$14 -> 3042.32 | E23: =(D23)/表格_報價分析表[[#This Row],[報價金額(未稅)]] -> 0.74707292 | F23: 0.2
A24: =表格_BOM[[#Totals],[Total Cost]]*(100%+表格_報價分析表[[#This Row],[倍率(不參考)]]) -> 4106.256 | B24: =表格_報價分析表[[#This Row],[報價金額(未稅)]]-表格_BOM[[#Totals],[Total Cost]] -> 712.656 | C24: =表格_報價分析表[[#This Row],[利潤]]/表格_報價分析表[[#This Row],[報價金額(未稅)]] -> 0.17355372 | D24: =表格_報價分析表[[#This Row],[報價金額(未稅)]]-表格_BOM[[#Totals],[Total Cost]]+'03 成本統計表'!$F$3+'03 成本統計表'!$F$14 -> 3076.256 | E24: =(D24)/表格_報價分析表[[#This Row],[報價金額(未稅)]] -> 0.74916323 | F24: 0.21
A25: =表格_BOM[[#Totals],[Total Cost]]*(100%+表格_報價分析表[[#This Row],[倍率(不參考)]]) -> 4140.192 | B25: =表格_報價分析表[[#This Row],[報價金額(未稅)]]-表格_BOM[[#Totals],[Total Cost]] -> 746.592 | C25: =表格_報價分析表[[#This Row],[利潤]]/表格_報價分析表[[#This Row],[報價金額(未稅)]] -> 0.18032787 | D25: =表格_報價分析表[[#This Row],[報價金額(未稅)]]-表格_BOM[[#Totals],[Total Cost]]+'03 成本統計表'!$F$3+'03 成本統計表'!$F$14 -> 3110.192 | E25: =(D25)/表格_報價分析表[[#This Row],[報價金額(未稅)]] -> 0.75121927 | F25: 0.22
... A73: =表格_BOM[[#Totals],[Total Cost]]*(100%+表格_報價分析表[[#This Row],[倍率(不參考)]]) -> 5769.12 | B73: =表格_報價分析表[[#This Row],[報價金額(未稅)]]-表格_BOM[[#Totals],[Total Cost]] -> 2375.52 | C73: =表格_報價分析表[[#This Row],[利潤]]/表格_報價分析表[[#This Row],[報價金額(未稅)]] -> 0.41176471 | D73: =表格_報價分析表[[#This Row],[報價金額(未稅)]]-表格_BOM[[#Totals],[Total Cost]]+'03 成本統計表'!$F$3+'03 成本統計表'!$F$14 -> 4739.12 | E73: =(D73)/表格_報價分析表[[#This Row],[報價金額(未稅)]] -> 0.82146324 | F73: 0.7
A74: "※ 現況定義 毛利 = 營收 - 專案成本(材料+外包+交通、住宿、津貼、保險...等) 利潤 = 毛利 - 加雲營業費用(12%管銷 ...等) - 加雲內部成本(人力薪資、出差、加班、加給) ※ 未來定義 毛利 = 營收 - 專案成本(材料+外包+交通、住宿、津貼、保險...等) - 加雲內部成本(人力薪資、出差、加班、加給) 利潤 = 毛利 - 加雲營業費用(12%管銷 ...等)"

Sheet 標案分析
A1: ='01參數設定'!B4 & " 標案預算" -> 標案預算 | F1: 加雲標準BOM 目前Cost(未稅)
F2: 總成本 | H2: 外部成本
A3: 折價比例 | B3: 未稅金額 | C3: 含稅金額 | F3: =表格_BOM[[#Totals],[Total Cost]] -> 3393.6 | H3: =SUM('03 成本統計表'!$F$4:$F$12)+'03 成本統計表'!$F$15 -> 1030
A4: 1 | B4: ='01參數設定'!B5 -> 1000000 | C4: =B4*1.05 -> 1050000 | F4: 利潤 | G4: 利潤率 | H4: 毛利 | I4: 毛利率
A5: 0.99 | B5: =$B$4*A5 -> 990000 | C5: =B5*1.05 -> 1039500 | F5: =B5-$F$3 -> 986606.4 | G5: =($B5-$F$3)/$B5 -> 0.99657212 | H5: =B5-$H$3 -> 988970 | I5: =H5/B5 -> 0.9989596
A6: 0.98 | B6: =$B$4*A6 -> 980000 | C6: =B6*1.05 -> 1029000 | F6: =B6-$F$3 -> 976606.4 | G6: =($B6-$F$3)/$B6 -> 0.99653714 | H6: =B6-$H$3 -> 978970 | I6: =H6/B6 -> 0.99894898
A7: 0.97 | B7: =$B$4*A7 -> 970000 | C7: =B7*1.05 -> 1018500 | F7: =B7-$F$3 -> 966606.4 | G7: =($B7-$F$3)/$B7 -> 0.99650144 | H7: =B7-$H$3 -> 968970 | I7: =H7/B7 -> 0.99893814
A8: 0.96 | B8: =$B$4*A8 -> 960000 | C8: =B8*1.05 -> 1008000 | F8: =B8-$F$3 -> 956606.4 | G8: =($B8-$F$3)/$B8 -> 0.996465 | H8: =B8-$H$3 -> 958970 | I8: =H8/B8 -> 0.99892708
A9: 0.95 | B9: =$B$4*A9 -> 950000 | C9: =B9*1.05 -> 997500 | F9: =B9-$F$3 -> 946606.4 | G9: =($B9-$F$3)/$B9 -> 0.99642779 | H9: =B9-$H$3 -> 948970 | I9: =H9/B9 -> 0.99891579
A10: 0.94 | B10: =$B$4*A10 -> 940000 | C10: =B10*1.05 -> 987000 | F10: =B10-$F$3 -> 936606.4 | G10: =($B10-$F$3)/$B10 -> 0.99638979 | H10: =B10-$H$3 -> 938970 | I10: =H10/B10 -> 0.99890426
A11: 0.93 | B11: =$B$4*A11 -> 930000 | C11: =B11*1.05 -> 976500 | F11: =B11-$F$3 -> 926606.4 | G11: =($B11-$F$3)/$B11 -> 0.99635097 | H11: =B11-$H$3 -> 928970 | I11: =H11/B11 -> 0.99889247
A12: 0.92 | B12: =$B$4*A12 -> 920000 | C12: =B12*1.05 -> 966000 | F12: =B12-$F$3 -> 916606.4 | G12: =($B12-$F$3)/$B12 -> 0.9963113 | H12: =B12-$H$3 -> 918970 | I12: =H12/B12 -> 0.99888043
A13: 0.91 | B13: =$B$4*A13 -> 910000 | C13: =B13*1.05 -> 955500 | F13: =B13-$F$3 -> 906606.4 | G13: =($B13-$F$3)/$B13 -> 0.99627077 | H13: =B13-$H$3 -> 908970 | I13: =H13/B13 -> 0.99886813
A14: 0.9 | B14: =$B$4*A14 -> 900000 | C14: =B14*1.05 -> 945000 | F14: =B14-$F$3 -> 896606.4 | G14: =($B14-$F$3)/$B14 -> 0.99622933 | H14: =B14-$H$3 -> 898970 | I14: =H14/B14 -> 0.99885556
A15: =A5-0.01 -> 0.98 | B15: =$B$4*A15 -> 980000 | C15: =B15*1.05 -> 1029000 | F15: =B15-$F$3 -> 976606.4 | G15: =($B15-$F$3)/$B15 -> 0.99653714 | H15: =B15-$H$3 -> 978970 | I15: =H15/B15 -> 0.99894898
A16: =A15-0.01 -> 0.97 | B16: =$B$4*A16 -> 970000 | C16: =B16*1.05 -> 1018500 | F16: =B16-$F$3 -> 966606.4 | G16: =($B16-$F$3)/$B16 -> 0.99650144 | H16: =B16-$H$3 -> 968970 | I16: =H16/B16 -> 0.99893814
A17: =A16-0.01 -> 0.96 | B17: =$B$4*A17 -> 960000 | C17: =B17*1.05 -> 1008000 | F17: =B17-$F$3 -> 956606.4 | G17: =($B17-$F$3)/$B17 -> 0.996465 | H17: =B17-$H$3 -> 958970 | I17: =H17/B17 -> 0.99892708
A18: =A17-0.01 -> 0.95 | B18: =$B$4*A18 -> 950000 | C18: =B18*1.05 -> 997500 | F18: =B18-$F$3 -> 946606.4 | G18: =($B18-$F$3)/$B18 -> 0.99642779 | H18: =B18-$H$3 -> 948970 | I18: =H18/B18 -> 0.99891579
A19: =A18-0.01 -> 0.94 | B19: =$B$4*A19 -> 940000 | C19: =B19*1.05 -> 987000 | F19: =B19-$F$3 -> 936606.4 | G19: =($B19-$F$3)/$B19 -> 0.99638979 | H19: =B19-$H$3 -> 938970 | I19: =H19/B19 -> 0.99890426
A20: =A19-0.01 -> 0.93 | B20: =$B$4*A20 -> 930000 | C20: =B20*1.05 -> 976500 | F20: =B20-$F$3 -> 926606.4 | G20: =($B20-$F$3)/$B20 -> 0.99635097 | H20: =B20-$H$3 -> 928970 | I20: =H20/B20 -> 0.99889247
A21: =A20-0.01 -> 0.92 | B21: =$B$4*A21 -> 920000 | C21: =B21*1.05 -> 966000 | F21: =B21-$F$3 -> 916606.4 | G21: =($B21-$F$3)/$B21 -> 0.9963113 | H21: =B21-$H$3 -> 918970 | I21: =H21/B21 -> 0.99888043
A22: =A21-0.01 -> 0.91 | B22: =$B$4*A22 -> 910000 | C22: =B22*1.05 -> 955500 | F22: =B22-$F$3 -> 906606.4 | G22: =($B22-$F$3)/$B22 -> 0.99627077 | H22: =B22-$H$3 -> 908970 | I22: =H22/B22 -> 0.99886813
A23: =A22-0.01 -> 0.9 | B23: =$B$4*A23 -> 900000 | C23: =B23*1.05 -> 945000 | F23: =B23-$F$3 -> 896606.4 | G23: =($B23-$F$3)/$B23 -> 0.99622933 | H23: =B23-$H$3 -> 898970 | I23: =H23/B23 -> 0.99885556
A24: =A23-0.01 -> 0.89 | B24: =$B$4*A24 -> 890000 | C24: =B24*1.05 -> 934500 | F24: =B24-$F$3 -> 886606.4 | G24: =($B24-$F$3)/$B24 -> 0.99618697 | H24: =B24-$H$3 -> 888970 | I24: =H24/B24 -> 0.9988427
A25: =A24-0.01 -> 0.88 | B25: =$B$4*A25 -> 880000 | C25: =B25*1.05 -> 924000 | F25: =B25-$F$3 -> 876606.4 | G25: =($B25-$F$3)/$B25 -> 0.99614364 | H25: =B25-$H$3 -> 878970 | I25: =H25/B25 -> 0.99882955
A26: =A25-0.01 -> 0.87 | B26: =$B$4*A26 -> 870000 | C26: =B26*1.05 -> 913500 | F26: =B26-$F$3 -> 866606.4 | G26: =($B26-$F$3)/$B26 -> 0.99609931 | H26: =B26-$H$3 -> 868970 | I26: =H26/B26 -> 0.99881609
A27: =A26-0.01 -> 0.86 | B27: =$B$4*A27 -> 860000 | C27: =B27*1.05 -> 903000 | F27: =B27-$F$3 -> 856606.4 | G27: =($B27-$F$3)/$B27 -> 0.99605395 | H27: =B27-$H$3 -> 858970 | I27: =H27/B27 -> 0.99880233
... A44: =A43-0.01 -> 0.69 | B44: =$B$4*A44 -> 690000 | C44: =B44*1.05 -> 724500 | F44: =B44-$F$3 -> 686606.4 | G44: =($B44-$F$3)/$B44 -> 0.99508174 | H44: =B44-$H$3 -> 688970 | I44: =H44/B44 -> 0.99850725
A45: 過去相關專案得標價格落點，用黃底標註。 未考量內容數量問題，只單純價格分析

Sheet 計算
A1: *** 要保持隱藏的工作表 ***
K3: =SUM(#REF!)-SUM(K6:K9) -> #REF! | L3: =ROUND(K3,0) -> #REF! | M3: 其他總計
L4: =ROUNDUP(SUM(#REF!),0) -> #REF! | M4: 雜貨總計
E6: {=IFERROR(INDEX(#REF!,MATCH(,COUNTIF($E$5:E5,#REF!),)),"")} | F6: =SUMIFS(#REF!,#REF!,E6) -> #REF! | G6: =F6+ROW()/1000000 -> #REF! | H6: =LARGE($G$6:$G$21,1) -> #REF! | I6: =MATCH(H6,$G$6:$G$21,0) -> #REF! | J6: =INDEX($E$6:$E$21,$I6) -> #REF! | K6: =INDEX($F$6:$F$21,$I6) -> #REF! | L6: =ROUND(K6,0) -> #REF! | M6: =UPPER(J6) & "總計" -> #REF!
E7: {=IFERROR(INDEX(#REF!,MATCH(,COUNTIF($E$5:E6,#REF!),)),"")} | F7: =SUMIFS(#REF!,#REF!,E7) -> #REF! | G7: =F7+ROW()/1000000 -> #REF! | H7: =LARGE($G$6:$G$21,2) -> #REF! | I7: =MATCH(H7,$G$6:$G$21,0) -> #REF! | J7: =INDEX($E$6:$E$21,$I7) -> #REF! | K7: =INDEX($F$6:$F$21,$I7) -> #REF! | L7: =ROUND(K7,0) -> #REF! | M7: =UPPER(J7) & "總計" -> #REF!
E8: {=IFERROR(INDEX(#REF!,MATCH(,COUNTIF($E$5:E7,#REF!),)),"")} | F8: =SUMIFS(#REF!,#REF!,E8) -> #REF! | G8: =F8+ROW()/1000000 -> #REF! | H8: =LARGE($G$6:$G$21,3) -> #REF! | I8: =MATCH(H8,$G$6:$G$21,0) -> #REF! | J8: =INDEX($E$6:$E$21,$I8) -> #REF! | K8: =INDEX($F$6:$F$21,$I8) -> #REF! | L8: =ROUND(K8,0) -> #REF! | M8: =UPPER(J8) & "總計" -> #REF!
E9: {=IFERROR(INDEX(#REF!,MATCH(,COUNTIF($E$5:E8,#REF!),)),"")} | F9: =SUMIFS(#REF!,#REF!,E9) -> #REF! | G9: =F9+ROW()/1000000 -> #REF! | H9: =LARGE($G$6:$G$21,4) -> #REF! | I9: =MATCH(H9,$G$6:$G$21,0) -> #REF! | J9: =INDEX($E$6:$E$21,$I9) -> #REF! | K9: =INDEX($F$6:$F$21,$I9) -> #REF! | L9: =ROUND(K9,0) -> #REF! | M9: =UPPER(J9) & "總計" -> #REF!
E10: {=IFERROR(INDEX(#REF!,MATCH(,COUNTIF($E$5:E9,#REF!),)),"")} | F10: =SUMIFS(#REF!,#REF!,E10) -> #REF! | G10: =F10+ROW()/1000000 -> #REF!
E11: {=IFERROR(INDEX(#REF!,MATCH(,COUNTIF($E$5:E10,#REF!),)),"")} | F11: =SUMIFS(#REF!,#REF!,E11) -> #REF! | G11: =F11+ROW()/1000000 -> #REF!
E12: {=IFERROR(INDEX(#REF!,MATCH(,COUNTIF($E$5:E11,#REF!),)),"")} | F12: =SUMIFS(#REF!,#REF!,E12) -> #REF! | G12: =F12+ROW()/1000000 -> #REF!
E13: {=IFERROR(INDEX(#REF!,MATCH(,COUNTIF($E$5:E12,#REF!),)),"")} | F13: =SUMIFS(#REF!,#REF!,E13) -> #REF! | G13: =F13+ROW()/1000000 -> #REF!
E14: {=IFERROR(INDEX(#REF!,MATCH(,COUNTIF($E$5:E13,#REF!),)),"")} | F14: =SUMIFS(#REF!,#REF!,E14) -> #REF! | G14: =F14+ROW()/1000000 -> #REF!
E15: {=IFERROR(INDEX(#REF!,MATCH(,COUNTIF($E$5:E14,#REF!),)),"")} | F15: =SUMIFS(#REF!,#REF!,E15) -> #REF! | G15: =F15+ROW()/1000000 -> #REF!
E16: {=IFERROR(INDEX(#REF!,MATCH(,COUNTIF($E$5:E15,#REF!),)),"")} | F16: =SUMIFS(#REF!,#REF!,E16) -> #REF! | G16: =F16+ROW()/1000000 -> #REF!
E17: {=IFERROR(INDEX(#REF!,MATCH(,COUNTIF($E$5:E16,#REF!),)),"")} | F17: =SUMIFS(#REF!,#REF!,E17) -> #REF! | G17: =F17+ROW()/1000000 -> #REF!
E18: {=IFERROR(INDEX(#REF!,MATCH(,COUNTIF($E$5:E17,#REF!),)),"")} | F18: =SUMIFS(#REF!,#REF!,E18) -> #REF! | G18: =F18+ROW()/1000000 -> #REF!
E19: {=IFERROR(INDEX(#REF!,MATCH(,COUNTIF($E$5:E18,#REF!),)),"")} | F19: =SUMIFS(#REF!,#REF!,E19) -> #REF! | G19: =F19+ROW()/1000000 -> #REF!
E20: {=IFERROR(INDEX(#REF!,MATCH(,COUNTIF($E$5:E19,#REF!),)),"")} | F20: =SUMIFS(#REF!,#REF!,E20) -> #REF! | G20: =F20+ROW()/1000000 -> #REF!
E21: {=IFERROR(INDEX(#REF!,MATCH(,COUNTIF($E$5:E20,#REF!),)),"")} | F21: =SUMIFS(#REF!,#REF!,E21) -> #REF! | G21: =F21+ROW()/1000000 -> #REF!

Sheet 管理分析
A1: 項目 | B1: 數值 | C1: 單位 | D1: 說明
A2: 外部成本 | B2: =SUM('03 成本統計表'!$F$4:$F$12)+'03 成本統計表'!$F$15 -> 1030 | C2: NTD | D2: 純設備、外包支出
A3: 內部費用 | B3: ='03 成本統計表'!F14 -> 363.6 | C3: NTD | D3: 不可動用，公司營運費
A4: 專案總成本 | B4: =SUM('03 成本統計表'!F4:F11)+'03 成本統計表'!F15 -> 1000 | C4: NTD | D4: 專案經理可使用
A5: 保固金 | B5: ='03 成本統計表'!F12 -> 30 | C5: NTD | D5: 工程結束後，預先凍結費用
A6: 專案總人天 | B6: ='03 成本統計表'!E3/4000 -> 0.5 | C6: 人天 | D6: 工程團隊可執行人天數
A7: 專案總人天（%） | B7: =(B6/B8) -> 8.9798851e-05 | C7: % | D7: 說明本案人天數，在整年度部門人力的佔比，用於評估資源佔用度
A8: 執行團隊總人天（年度） | B8: =24*(247-15) -> 5568 | C8: 人天 | D8: 整個部分，整年度總人天(扣除部門主管及副主管＋助理)共24人
